<?xml version="1.0"?>
<robot xmlns:xacro="http://wiki.ros.org/xacro" name="test">

  <xacro:property name="H" value="2" />

  <xacro:property name="chest_width" value = "${H*0.3662}" />
  <xacro:property name="chest_depth" value = "${H*0.30}" />
  <xacro:property name="chest_height" value = "${H*0.6966}" />

  <!-- Add for independent usage of the person model -->
  <link name="world"/>
  <!-- Chair model -->

  <link name="chair_base" >
    <inertial>
      <origin xyz="0.0 0.0 0.0" />
      <mass value="1.0" />
      <inertia  ixx="1.0" ixy="0.0"  ixz="0.0"  iyy="100.0"  iyz="0.0"  izz="1.0" />
    </inertial>
    <visual>
      <origin xyz="0.0 0.0 0.0" rpy="0.0 0.0 0.0" />
      <geometry>
        <box size="0.60 1.00 0.30"/>
      </geometry>
      <material name="LightGrey">
        <color rgba="0.1 0.1 0.1 1"/>
      </material>
    </visual>
    <collision>
      <origin xyz="0.0 0.0 0.0" rpy="0.0 0.0 0.0" />
      <geometry>
        <box size="0.60 1.00 0.30"/>
      </geometry>
    </collision>
  </link>
  <gazebo reference="chair_base">
    <material>Gazebo/Gray</material>
  </gazebo>

  <joint name="chair_base_joint" type="fixed">
    <parent link="world" />
    <child link = "chair_base" />
    <origin xyz="0.0 0.78 0.15" rpy="0.0 0.0 0.0" />
  </joint>

  <!-- Hip -->

  <link name="body_hip" >
    <inertial>
      <origin xyz="0.0 0.0 0.0" />
      <mass value="1.0" />
      <inertia  ixx="1.0" ixy="0.0"  ixz="0.0"  iyy="100.0"  iyz="0.0"  izz="1.0" />
    </inertial>
    <visual>
      <geometry>
        <box size="0.50 0.40 0.40"/>
        <!--box size="0.40 0.20 0.50"/--> 
      </geometry>
      <material name="red">
          <color rgba="1 0 0 1"/>
      </material>
    </visual>
    <collision>
      <origin xyz="0.0 0.0 0.0" rpy="0.0 0.0 0.0" />
      <geometry>
        <box size="0.50 0.40 0.40"/>
        <!--box size="0.40 0.20 0.50"/-->     <!-- (0.387*H) chest height in y direction, (0.259*H)  chest width in z direction-->
      </geometry>
    </collision>
  </link>
  <gazebo reference="body_hip">
    <material>Gazebo/Red</material>
  </gazebo>

  <joint name="body_hip_joint" type="fixed">
   <parent link="chair_base" />
   <child link = "body_hip" />
   <origin xyz="0.0 0.0 0.35" rpy="0.0 0.0 0.0"/>
   <!--origin xyz="0.0 -0.40 -0.2273" rpy="1.57 0.0 -1.57" /-->  <!-- (0.0 -0.40 0.1483)  -->
  </joint>

<!-- Chest -->
  <link name="body_chest" >
    <inertial>
      <origin xyz="0.0 0.0 0.0" />
      <mass value="1.0" />
      <inertia  ixx="1.0" ixy="0.0"  ixz="0.0"  iyy="100.0"  iyz="0.0"  izz="1.0" />
    </inertial>
    <visual>
      <origin xyz="0.0 0.0 0.0" rpy="0.0 0.0 0.0" />
      <geometry>
        <box size="${chest_width} ${chest_depth}  ${chest_height}"/>
        <!--box size="0.30 0.6966  0.3662"/-->     <!-- (0.387*H) chest height in y direction, (0.259*H)  chest width in z direction-->
      </geometry>
      <material name="red">
        <color rgba="1 0 0 1"/>
      </material>
    </visual>
    <collision>
      <origin xyz="0.0 0.0 0.0" rpy="0.0 0.0 0.0" />
      <geometry>
        <box size="${chest_width} ${chest_depth}  ${chest_height}"/>
        <!--box size="0.30 0.6966  0.3662"/-->     <!-- (0.387*H) chest height in y direction, (0.259*H)  chest width in z direction-->
      </geometry>
    </collision>
  </link>
  <gazebo reference="body_chest">
    <material>Gazebo/Red</material>
  </gazebo>

  <joint name="body_chest_joint" type="fixed">
    <parent link="body_hip" />
    <child link = "body_chest" />
    <origin xyz="0.0 0.35 0.20" rpy="0.0 0.0 0.0"/>
    <!--origin xyz="0.0 -0.05 0.0083" rpy="1.57 0.0 -1.57" /-->   <!-- (0.0 -0.25 0.1483)   (0.387*H/2)-20 origin in z direction -->
  </joint>

  <!-- Head -->
  <link name="body_head" >
    <inertial>
      <origin xyz="0.0 0.0 0.0" />
      <mass value="1.0" />
      <inertia  ixx="1.0" ixy="0.0"  ixz="0.0"  iyy="100.0"  iyz="0.0"  izz="1.0" />
    </inertial>
    <visual>
      <geometry>
        <sphere radius= "0.11"/>   <!-- (0.13*H/2) head radius -->
      </geometry>
      <material name="red">
        <color rgba="1 0 0 1"/>
      </material>
    </visual>
    <collision>
      <geometry>
        <sphere radius= "0.11"/>
      </geometry>
    </collision>
  </link>
  <gazebo reference="body_head">
    <material>Gazebo/Red</material>
  </gazebo>

  <joint name="body_head_joint" type="fixed">
    <parent link="body_chest" />
    <child link = "body_head" />
    <origin xyz="0.0 0.0 0.4583" rpy="0.0 0.0 0.0" />  <!-- 31 cm + head radius in y direction  -->
  </joint>

  <!-- Legs -->
  <link name="body_Lleg" >
    <inertial>
      <origin xyz="0.0 0.0 0.0" />
      <mass value="1.0" />
      <inertia  ixx="1.0" ixy="0.0"  ixz="0.0"  iyy="100.0"  iyz="0.0"  izz="1.0" />
    </inertial>
    <visual>
      <geometry>
        <box size="0.20 0.34 0.50"/>
      </geometry>
      <material name="red">
        <color rgba="1 0 0 1"/>
      </material>
    </visual>
    <collision>
      <origin xyz="0.0 0.0 0.0" rpy="0.0 0.0 0.0" />
      <geometry>
        <box size="0.20 0.34 0.50"/>
        <!--box size="0.30 0.6966  0.3662"/-->     <!-- (0.387*H) chest height in y direction, (0.259*H)  chest width in z direction-->
      </geometry>
    </collision>
  </link>
  <gazebo reference="body_Lleg">
    <material>Gazebo/Red</material>
  </gazebo>

  <joint name="body_Lleg_joint" type="fixed">
    <parent link="body_hip" />
    <child link = "body_Lleg" />
    <origin xyz="0.11 -0.28 0.0" rpy="0.0 0.0 0.0" />
  </joint>

  <link name="body_Rleg" >
    <inertial>
      <origin xyz="0.0 0.0 0.0" />
      <mass value="1.0" />
      <inertia  ixx="1.0" ixy="0.0"  ixz="0.0"  iyy="100.0"  iyz="0.0"  izz="1.0" />
    </inertial>
    <visual>
      <geometry>
        <box size="0.20 0.34 0.50"/>
      </geometry>
      <material name="red">
        <color rgba="1 0 0 1"/>
      </material>
    </visual>
    <collision>
      <origin xyz="0.0 0.0 0.0" rpy="0.0 0.0 0.0" />
      <geometry>
        <box size="0.20 0.34 0.50"/>
        <!--box size="0.30 0.6966  0.3662"/-->     <!-- (0.387*H) chest height in y direction, (0.259*H)  chest width in z direction-->
      </geometry>
    </collision>
  </link>
  <gazebo reference="body_Rleg">
    <material>Gazebo/Red</material>
  </gazebo>

  <joint name="body_Rleg_joint" type="fixed">
    <parent link="body_hip" />
    <child link = "body_Rleg" />
    <origin xyz="-0.11 -0.28 0.0" rpy="0.0 0.0 0.0" />
  </joint>


<!-- Left Arm -->
  <link name="left_shoulder">
    <inertial>
      <origin xyz="0.0 0.0 0.0" />
      <mass value="1.0" />
      <inertia  ixx="1.0" ixy="0.0"  ixz="0.0"  iyy="100.0"  iyz="0.0"  izz="1.0" />
    </inertial>
    <visual>
      <origin rpy="0 0 0" xyz="0 0 0"/>
      <geometry>
        <sphere radius="0.05"/>
      </geometry>
    </visual>
    <collision>
      <geometry>
        <sphere radius= "0.05"/>
      </geometry>
    </collision>
  </link>
  <gazebo reference="left_shoulder">
    <material>Gazebo/Red</material>
  </gazebo>

  <joint name="LShoulder" type="fixed" >
    <origin xyz="0.2331 0.0 0.2855" />
    <!--origin xyz="0.3583 0.0 0.2855" /-->   <!-- (0.259*H)/2 width in z direction, (0.387*H)/2 chest height in y direction  -->
    <parent link="body_chest" />
    <child link="left_shoulder" />
  </joint>

  <link name="left_humerus">
    <inertial>
      <origin xyz="0.0 0.0 0.0" />
      <mass value="1.0" />
      <inertia  ixx="1.0" ixy="0.0"  ixz="0.0"  iyy="100.0"  iyz="0.0"  izz="1.0" />
    </inertial>
    <visual>
      <origin rpy="0 0 0" xyz="0 0 0.1692"/>
      <geometry>
        <cylinder radius="0.05" length="0.3384"/> <!-- 0.188 H lenght   -->
      </geometry>
      <material name="red">
        <color rgba="1 0 0 1"/>
      </material>
    </visual>
    <collision>
      <origin rpy="0 0 0" xyz="0 0 0.1692"/>
      <geometry>
        <cylinder radius="0.05" length="0.3384"/>
      </geometry>
    </collision>
  </link>
  <gazebo reference="left_humerus">
    <material>Gazebo/Red</material>
  </gazebo>


  <joint name="pilar_arm_joint_x" type="revolute">
    <limit effort="1000.0" lower="-3.14" upper="3.14" velocity="0.5"/>
    <!--limit effort="1000.0" lower="1.57" upper="-1.57" velocity="0.2" /-->
    <axis xyz= "1 0 0" />
    <parent link="left_shoulder" />
    <child link = "virtual_shoulder_y" />
    <origin xyz="0.0 0.0 0.0" rpy="0.0 0.0 0.0" />
  </joint>

  <link name="virtual_shoulder_y">
    <inertial>
      <origin xyz="0.0 0.0 0.0" />
      <mass value="1.0" />
      <inertia  ixx="1.0" ixy="0.0"  ixz="0.0"  iyy="100.0"  iyz="0.0"  izz="1.0" />
    </inertial>
  </link>

  <joint name="pilar_arm_joint_y" type="revolute">
    <limit effort="1000.0" lower="-3.14" upper="3.14" velocity="0.5"/>
    <!--limit effort="1000.0" lower="1.57" upper="-1.57" velocity="0.2" /-->
    <axis xyz= "0 1 0" />
    <parent link="virtual_shoulder_y" />
    <child link = "virtual_shoulder_z" />
    <origin xyz="0.0 0.0 0.0" rpy="0.0 0.0 0.0" />
  </joint>

  <link name="virtual_shoulder_z">
    <inertial>
      <origin xyz="0.0 0.0 0.0" />
      <mass value="1.0" />
      <inertia  ixx="1.0" ixy="0.0"  ixz="0.0"  iyy="100.0"  iyz="0.0"  izz="1.0" />
    </inertial>
  </link>

  <joint name="pilar_arm_joint_z" type="revolute">
    <limit effort="1000.0" lower="-3.14" upper="3.14" velocity="0.5"/>
    <!--limit effort="1000.0" lower="1.57" upper="-1.57" velocity="0.2" /-->
    <axis xyz= "0 0 1" />
    <parent link="virtual_shoulder_z" />
    <child link = "left_humerus" />
    <origin xyz="0.0 0.0 0.0" rpy="0.0 0.0 0.0" />
  </joint>

  <link name="left_elbow_joint">
    <inertial>
      <origin xyz="0.0 0.0 0.0" />
      <mass value="1.0" />
      <inertia  ixx="1.0" ixy="0.0"  ixz="0.0"  iyy="100.0"  iyz="0.0"  izz="1.0" />
    </inertial>
    <visual>
      <origin rpy="0 0 0" xyz="0 0 0"/>
      <geometry>
        <cylinder radius="0.01" length="0.1"/>
      </geometry>
      <material name="LightGrey">
        <color rgba="0.7 0.7 0.7 1.0"/>
      </material>
    </visual>
    <collision>
      <geometry>
        <cylinder radius="0.01" length="0.1"/>
      </geometry>
    </collision>
  </link>
  <gazebo reference="left_elbow_joint">
    <material>Gazebo/Gray</material>
  </gazebo>

  <joint name="LElbow" type="revolute" >
    <limit effort="1000.0" lower="-2.67" upper="0" velocity="0.5" />
    <origin rpy="4.71239 0 0" xyz="0 0 0.3384"/>   <!-- z values changes with dimension of the body , 0.188*H/2 -->
    <axis xyz="0 0 1" />
    <parent link="left_humerus" />
    <child link="left_elbow_joint" />
  </joint>

    <!-- left hand -->

  <link name="left_fore_arm">
    <inertial>
      <origin xyz="0.0 0.0 0.0" />
      <mass value="1.0" />
      <inertia  ixx="1.0" ixy="0.0"  ixz="0.0"  iyy="100.0"  iyz="0.0"  izz="1.0" />
    </inertial>
    <visual>
      <origin rpy="0 0 0" xyz="0 0 0 "/>
      <geometry>
        <cylinder radius="0.05" length="0.261"/> <!-- length values changes with dimension of the body 0.145*H -->
      </geometry>
    </visual>
    <collision>
      <geometry>
        <cylinder radius="0.05" length="0.261"/>
      </geometry>
    </collision>
  </link>
  <gazebo reference="left_fore_arm">
    <material>Gazebo/Red</material>
  </gazebo>

  <joint name="LForeArm" type="fixed" >
    <origin rpy="1.5708 0 0" xyz="0.0 -0.1305 0.0" /> <!-- y values changes with dimension of the body, 0.145*H/2  -->
    <parent link="left_elbow_joint" />
    <child link="left_fore_arm" />
  </joint>

  <link name="left_wrist">
    <inertial>
      <origin xyz="0.0 0.0 0.0" />
      <mass value="1.0" />
      <inertia  ixx="1.0" ixy="0.0"  ixz="0.0"  iyy="100.0"  iyz="0.0"  izz="1.0" />
    </inertial>
    <visual>
      <origin rpy="0 0 0" xyz="0 0 0"/>
      <geometry>
        <sphere radius="0.05"/>
      </geometry>
    </visual>
    <collision>
      <geometry>
        <sphere radius= "0.05"/>
      </geometry>
    </collision>
  </link>
  <gazebo reference="left_wrist">
    <material>Gazebo/Red</material>
  </gazebo>

  <joint name="LWrist" type="fixed" >
    <origin xyz="0 0 0.1305" />   <!-- values changes with dimension of the body, 0.145*H/2 -->
    <parent link="left_fore_arm" />
    <child link="left_wrist" />
  </joint>

  <link name="left_wrist_psi_link" >
    <inertial>
      <origin xyz="0.0 0.0 0.0" />
      <mass value="1.0" />
      <inertia  ixx="1.0" ixy="0.0"  ixz="0.0"  iyy="100.0"  iyz="0.0"  izz="1.0" />
    </inertial>
  </link>
  <gazebo reference="left_wrist_psi_link">
    <material>Gazebo/Red</material>
  </gazebo>

  <joint name="LWristPsi" type="revolute" >
    <!-- <limit effort="1000.0" lower="-1.48" upper="1.57" velocity="0.5" /> -->
    <limit effort="1000.0" lower="-3.14" upper="3.14" velocity="0.5" />
    <origin rpy="0 0 0" />
    <parent link="left_wrist" />
    <child link="left_wrist_psi_link" />
    <axis xyz="0 0 1" />
  </joint>


  <link name="left_wrist_theta_link" >
    <inertial>
      <origin xyz="0.0 0.0 0.0" />
      <mass value="1.0" />
      <inertia  ixx="1.0" ixy="0.0"  ixz="0.0"  iyy="100.0"  iyz="0.0"  izz="1.0" />
    </inertial>
  </link>
  <gazebo reference="left_wrist_theta_link">
    <material>Gazebo/Red</material>
  </gazebo>

  <joint name="LWristTheta" type="revolute" >
    <!-- <limit effort="1000.0" lower="-1.48" upper="1.48" velocity="0.5" /> -->
    <limit effort="1000.0" lower="-3.14" upper="3.14" velocity="0.5" />
    <origin rpy="1.5708 0 0" />
    <parent link="left_wrist_psi_link"/>
    <child link="left_wrist_theta_link"/>
    <axis xyz="0 0 1" />
  </joint>


  <link name="left_wrist_phi_link" >
    <inertial>
      <origin xyz="0.0 0.0 0.0" />
      <mass value="1.0" />
      <inertia  ixx="1.0" ixy="0.0"  ixz="0.0"  iyy="100.0"  iyz="0.0"  izz="1.0" />
    </inertial>
  </link>
  <gazebo reference="left_wrist_phi_link">
    <material>Gazebo/Red</material>
  </gazebo>

  <joint name="LWristPhi" type="revolute" >
    <!-- <limit effort="1000.0" lower="-0.78" upper="0.78" velocity="0.5" /> -->
    <limit effort="1000.0" lower="-3.14" upper="3.14" velocity="0.5" />
    <parent link="left_wrist_theta_link"/>
    <child link="left_wrist_phi_link"/>
    <!-- <child link="right_palm"/> -->
    <origin rpy="1.5708 0 1.5708" />
    <axis xyz="0 0 1" />
  </joint>


  <link name="left_palm">
    <inertial>
      <origin xyz="0.0 0.0 0.0" />
      <mass value="1.0" />
      <inertia  ixx="1.0" ixy="0.0"  ixz="0.0"  iyy="100.0"  iyz="0.0"  izz="1.0" />
    </inertial>
    <visual>
      <origin rpy="0 0 0" xyz="0 0 0"/>
      <geometry>
        <box size="0.09 0.04 0.1944"/>
      </geometry>
    </visual>
    <collision>
      <origin rpy="0 0 0" xyz="0 0 0"/>
      <geometry>
        <box size="0.09 0.04 0.1944"/>
      </geometry>
    </collision>
  </link>
  <gazebo reference="left_palm">
    <material>Gazebo/Red</material>
  </gazebo>

  <joint name="LPalm" type="fixed" >
    <parent link="left_wrist_phi_link"/>
    <child link="left_palm"/>
    <origin rpy="-1.5708 0 -1.5708" xyz="0.0972 0 0"  />  <!-- x values changes with dimension of the body 0.108*H/2  -->
  </joint>


  <link name="left_palm_sensor">
    <inertial>
      <origin xyz="0.0 0.0 0.0" />
      <mass value="1.0" />
      <inertia  ixx="1.0" ixy="0.0"  ixz="0.0"  iyy="100.0"  iyz="0.0"  izz="1.0" />
    </inertial>
    <visual>
      <origin rpy="0 0 0" xyz="0 0 -0.04"/>
      <geometry>
        <cylinder radius="0.01" length="0.02"/>
      </geometry>
      <material name="LightGrey">
        <color rgba="0.7 0.7 0.7 1.0"/>
      </material>
    </visual>
    <collision>
      <origin rpy="0 0 0" xyz="0 0 -0.04"/>
      <geometry>
        <cylinder radius="0.01" length="0.02"/>
      </geometry>
    </collision>
  </link>
  <gazebo reference="left_palm_sensor">
    <material>Gazebo/Red</material>
  </gazebo>

  <joint name="LSensorPalm" type="fixed" >
    <parent link="left_palm"/>
    <child link="left_palm_sensor"/>
    <origin rpy="1.5708 0 0" xyz="0 0 0" />  <!-- z values changes with dimension of the body  -->
  </joint>

  <transmission name="arm_trans_x">
    <type>transmission_interface/SimpleTransmission</type>
    <joint name="pilar_arm_joint_x">
      <hardwareInterface>hardware_interface/EffortJointInterface</hardwareInterface>
    </joint>
    <actuator name="motor1">
      <mechanicalInterface>1</mechanicalInterface>
    </actuator>
  </transmission>

  <transmission name="arm_trans_y">
    <type>transmission_interface/SimpleTransmission</type>
    <joint name="pilar_arm_joint_y">
      <hardwareInterface>hardware_interface/EffortJointInterface</hardwareInterface>
    </joint>
    <actuator name="motor1">
      <mechanicalInterface>1</mechanicalInterface>
    </actuator>
  </transmission>

  <transmission name="arm_trans_z">
    <type>transmission_interface/SimpleTransmission</type>
    <joint name="pilar_arm_joint_z">
      <hardwareInterface>hardware_interface/EffortJointInterface</hardwareInterface>
    </joint>
    <actuator name="motor1">
      <mechanicalInterface>1</mechanicalInterface>
    </actuator>
  </transmission>

  <transmission name="LElbow_trans">
    <type>transmission_interface/SimpleTransmission</type>
    <joint name="LElbow">
      <hardwareInterface>hardware_interface/EffortJointInterface</hardwareInterface>
    </joint>
    <actuator name="motor1">
      <mechanicalInterface>1</mechanicalInterface>
    </actuator>
  </transmission>

  <transmission name="LWristPsi_trans">
    <type>transmission_interface/SimpleTransmission</type>
    <joint name="LWristPsi">
      <hardwareInterface>hardware_interface/EffortJointInterface</hardwareInterface>
    </joint>
    <actuator name="motor1">
      <mechanicalInterface>1</mechanicalInterface>
    </actuator>
  </transmission>

  <transmission name="LWristTheta_trans">
    <type>transmission_interface/SimpleTransmission</type>
    <joint name="LWristTheta">
      <hardwareInterface>hardware_interface/EffortJointInterface</hardwareInterface>
    </joint>
    <actuator name="motor1">
      <mechanicalInterface>1</mechanicalInterface>
    </actuator>
  </transmission>

  <transmission name="LWristPhi_trans">
    <type>transmission_interface/SimpleTransmission</type>
    <joint name="LWristPhi">
      <hardwareInterface>hardware_interface/EffortJointInterface</hardwareInterface>
    </joint>
    <actuator name="motor1">
      <mechanicalInterface>1</mechanicalInterface>
    </actuator>
  </transmission>

  <gazebo>
    <plugin name="gazebo_ros_control" filename="libgazebo_ros_control.so">
      <!--robotNamespace>simple_model</robotNamespace-->
      <!--robotSimType>gazebo_ros_control/DefaultRobotHWSim</robotSimType-->
      <!--legacyModeNS>true</legacyModeNS-->
    </plugin>
  </gazebo>


</robot>